Workbook

Sheet Sheet2
A2: 1-السخان | B2: مركزي مع سخان واحد 200L MILANO
B3: مركزي مع 2 سخان 200L كل واحد MILANO
B4: عادي فوق كل حمام ArIston
B5: مركزي مع 2 سخان 200L كل واحد ARISTON
A7: 2-كراسي الحمامات | B7: معلق مع سماكة جدار 25 سنتم
B8: عادي
B9: معلق بدون خزان سماكة جدار 25 سنتم
A11: 3- الشفط | B11: عادي
B12: مركزي مخفي للسطح او للجدران الخارجية
A14: 4-النعلة | B14: شامل النعلات - مخفية
B15: شامل النعلات - مخفية مع ستيل
B16: شامل النعلات - عادية
B17: بدون نعلة ( ستيل فقط)
A19: 5-الألمنيوم | B19: بروفايل فول امبريلا عادي
B20: بروفايل كيرتين وول
A22: 6- خزان المياه | B22: تحت الأرض مع غرفة | C22: =IF(#REF!="تحت الأرض","الغرفة طابوق متروس-كونكريت"," ") -> #REF!
B23: فوق الأرض
A25: 7- خزان استرجاع مياه التكييف | B25: غرفة تحت الأرض فقط
B26: غرفة تحت الارض مع خزان
B27: لا يوجد
A28: 8- مكسرات المغاسل والحمامات | B28: مخفية داخل الجدران
B29: عادية
A31: 9- الصرف | B31: كلين اوت | C31: =IF(#REF!="عادي","اتصالات-كهرباء-صرف","اتصالات-كهرباء") -> #REF!
B32: عادي
A34: 10-حبات السيراميك | B34: كبيرة
B35: متوسطة
B36: صغيرة
A38: 11- سعة خزان المياه | B38: 1000 جالون
B39: 2000 جالون
B40: 1500 جالون
A41: 12- ارتفاعات الأبواب | B41: 220 Cm
B42: 240 Cm
B43: 250 Cm
B44: حتى الجبس
A46: الباب الرئيسي | B46: عادي
B47: فيكس + عادي
B48: دبل هايت
A50: نوع الصبغ: | B50: قرافيو ناسونال
B51: سانديكس جوتن
B52: جوتاشيلد جوتن
...

Sheet المدخلات
B1: معلومات المشروع والمواصفات
B2: مدخلات الاستشاري | AD2: مدخلات المقاول
B3: المالك | P3: احمد ابراهيم النعيمي | AD3: اسم المقاول
B4: وصف المشروع | P4: فيلا دور أرضي و اول وسور | AD4: رقم رخصة المقاول
B5: الإمارة | P5: رأس الخيمة | AD5: مساحة البناء | AR5: 118 | AY5: 5549
B6: رقم هاتف المالك | AD6: المهندس المسوول
B7: تاريخ تعاقد الاستشاري و المالك: | AD7: يوم عقد المقاول: | AR7: =TODAY() -> 46021
B8: يوم عقد المالك: | P8: الاريعاء | AD8: قيمة التعاقد:
B9: أتعاب التصميم: | AD9: مدة التنفيذ: | AR9: 14 شهر
B10: أتعاب الاشراف الشهرية:
B11: المنطقة | P11: الخران | AD11: رقم هاتف المسؤول عن المقاولات
B12: رقم القسيمة | P12: 403100010
B13: عنوان المالك | P13: راس الخيمة
AD14: تاريخ تسليم الموقع:

Sheet حساب الكميات
B2: حساب كميات المشروع
B3: معلومات المشروع
B4: المالك | K4: =المدخلات!$P$3 -> احمد ابراهيم النعيمي | AD4: المنطقة | AQ4: =المدخلات!$P$11 -> الخران
B5: وصف المشروع | K5: =المدخلات!$P$4 -> فيلا دور أرضي و اول وسور | AD5: رقم القسيمة | AQ5: =المدخلات!$P$12 -> 403100010
B6: مساحة السور م.طولي | K6: =المدخلات!AR5 -> 118 | AD6: مساحة البناء بالقدم المربع | AQ6: =المدخلات!$AY$5 -> 5549
B24: بيانات المقاول
B25: اسم الشركة | F25: Contra name | K25: =المدخلات!$AR$3 -> 0 | AD25: المسوول | AI25: Engineer | AQ25: =المدخلات!$AR$6 -> 0
B26: تاريخ | E26: Date | K26: =المدخلات!$AR$7 -> 46021 | AD26: رقم الهاتف: | AI26: Phone No | AQ26: =المدخلات!$AR$11 -> 0
B27: License number | K27: =المدخلات!$AR$4 -> 0 | AD27: مدة تنفيذ | AI27: Construction period | AQ27: =المدخلات!$AR$9 -> 14 شهر
B29: عرض السعر / Price OFFER | AQ29: ختم الشركة العارضة / Contractor Stamp
B30: تكلفة انشاء وانجاز الفيلا | P30: Total villa cost | AD30: =AO236 -> 67665 | AQ30: =المدخلات!AR10 -> 0
B31: تكلفة انشاء وإنجاز السور | P31: Total Boundary wall cost | AD31: =AY231 -> 0
B32: تكلفة انشاء وإنجاز الفيلا | P32: Total Villa and Boundary wall | AD32: =AD30+AD31+AO239 -> 67665
B33: الضريبة | P33: VAT | AD33: =AD32*0.05 -> 3383.25
B34: القيمة الاجمالية للمشروع شامل الضريبة | P34: Total project value with Vat | AD34: =AD32+AD33 -> 71048.25
B36: السعر المقدم بعد دراسة جميع بنود العقد والمواصفات ومطابقة جميع المخططات ومناظير ال 3D والموافقة عليها | AI36: The prices should include all contract activities m specification , confirming all drawings with project 3d
B37: حساب الكميات يجب ان يكون دقيق وان لا تتعدا الكميات 5% | AI37: Bill of Quantities should be accurate and not pass 5%
B38: علي المقاول الاستفسار من الاستشاري عن كل بند لم يكن واضحا في المناقصة . | AI38: contractor should send queries to consultant for any item not clear in the tender
B40: أولا : اعـــــمـــــــــال الـــــهــــيكــــــل | C40: أولا : أعمال الهيكل | AI40: english
C41: A | F41: أعمال المياه الجوفية و إحلال التربة وتجهز الموقع
C42: A1 | F42: تجفيف المياه الجوفية | Y42: Dewatering | AO42: L.S | AP42: M2 | AQ42: M2 | AR42: M2 | AS42: 0 | AW42: 1 | BA42: =AW42*AS42 -> 0
C43: A2 | F43: إحلال التربة | Y43: Soil replacement | AO43: L.S | AP43: M2 | AQ43: M2 | AR43: M2 | AS43: 0 | AW43: 1 | BA43: =AW43*AS43 -> 0
C44: A3 | F44: تجهيز الموقع | Y44: Mobilization | AO44: L.S | AP44: M2 | AQ44: M2 | AR44: M2 | AS44: 1 | AW44: 1 | BA44: =AW44*AS44 -> 1
C45: المياه الجوفية و إحلال التربة وتجهز الموقع | Y45: dewatering , soil replacement and Mobilization | AO45: =SUM(BA42:BD44) -> 1
C46: B | F46: أعمال تحت منسوب الأرض | AO46: substructure works
C47: B1 | F47: الحفر | X47: Excavation | AO47: M3 | AP47: M2 | AQ47: M2 | AR47: M2 | AS47: 1 | AW47: 1 | BA47: =AW47*AS47 -> 1
C48: B2 | F48: الرودبيس | X48: Road base | AO48: M3 | AP48: M2 | AQ48: M2 | AR48: M2 | AS48: 1 | AW48: 1 | BA48: =AW48*AS48 -> 1
C49: B3 | F49: خرسانة أسفل القواعد | X49: PCC under foundation | AO49: M3 | AP49: M2 | AQ49: M2 | AR49: M2 | AW49: 1 | BA49: =AW49*AS49 -> 0
C50: B4 | F50: خرسانة للقواعد | X50: RCC Foundation | AO50: M3 | AP50: M2 | AQ50: M2 | AR50: M2 | AS50: 1 | AW50: 1 | BA50: =AW50*AS50 -> 1
C51: B5 | F51: خرسانة مسلحة رقاب أعمدة | X51: Neck Columns | AO51: M3 | AP51: M2 | AQ51: M2 | AR51: M2 | AS51: 1 | AW51: 1 | BA51: =AW51*AS51 -> 1
C52: B6 | F52: طابوق مصمت أسفل الجسور الأرضية | X52: Solid block under tie beams | AO52: M2 | AS52: 1 | AW52: 1 | BA52: =AW52*AS52 -> 1
C53: B7 | F53: الجسور الأرضية | X53: Tie beams | AO53: M3 | AS53: 1 | AW53: 1 | BA53: =AW53*AS53 -> 1
C54: B8 | F54: عزل تحت منسوب الارض | X54: water proof for substructure | AO54: L.S | AS54: 1 | AW54: 1 | BA54: =AW54*AS54 -> 1
C55: B9 | F55: لوحات البولي ايثيلين | X55: Polythene sheet | AO55: L.S | AS55: 1 | AW55: 1 | BA55: =AW55*AS55 -> 1
C56: B10 | F56: الدفان والدمك | X56: back filling and compaction | AO56: M3 | AS56: 1 | AW56: 1 | BA56: =AW56*AS56 -> 1
C57: B11 | F57: الخرسانة الأرضية | X57: Flooring | AO57: M3 | AS57: 1 | AW57: 1 | BA57: =AW57*AS57 -> 1
C58: B12 | F58: معالجة النمل الأبيض (3مرات) | X58: Ant termite | AO58: L.S | AS58: 1 | AW58: 1 | BA58: =AW58*AS58 -> 1
C59: B13 | F59: غرفة المياه تحت الأرض | X59: Under ground water tank | AO59: L.S | AS59: 1 | AW59: 1 | BA59: =AW59*AS59 -> 1
C60: B14 | F60: غرفة استرجاع مياه التكييف تحت الأرض | X60: under ground tank for AC water | AO60: L.S | AS60: 1 | AW60: 1 | BA60: =AW60*AS60 -> 1
C61: B15 | F61: بالوعة الصرف الصحي | X61: septic tank | AO61: L.S | AP61: M2 | AQ61: M2 | AR61: M2 | AS61: 1 | AW61: 1 | BA61: =AW61*AS61 -> 1
...

Sheet اتفاق 01 (2)
B1: عقد اتفاق بين المالك و الاستشاري
B2: انه في يوم | D2: =المدخلات!$P$8 -> الاريعاء | E2: بتاريخ | F2: =المدخلات!$P$7 -> 0 | H2: حرر بين كل من: | J2: المنطقة | L2: =المدخلات!$P$11 -> الخران
B3: • | C3: الطرف الأول السيد | E3: =المدخلات!$P$3 -> احمد ابراهيم النعيمي | H3: القسيمة رقم | J3: =المدخلات!$P$12 -> 403100010 | L3: =المدخلات!$P$6 -> 0
B4: • | C4: لطرف الثاني: | E4: اشركة سافانا ديزاين للاستشارات الهندسية والتصميم الداخلي، رخصة رقم(48818)، وعنوانها مكتب رقم (407) بأبراج جلفار، في إمارة رأس الخيمة ، ويمثلها المدير / المهندس أيمن بن حمادي، وبعد أن أقر المتعاقدان بأهليتهما للتصرف والتعاقد اتفقا على ما يأتي:
B5: 1 | C5: قبل الطرف الثاني بموجب هذا العقد أن يقوم بأعمال التصميم الهندسي والإشراف عل مشروع الفيلا الخاصة بالطرف الأول، الوارد بياناتها في مقدمة هذا العقد، وذلك حسب المعايير والمواصفات المحددة من قبل الجهات المختصة.
B6: 2 | C6: يلتزم الطرف الأول بدفع مبلغ وقدره | H6: =المدخلات!$P$9 -> 0 | I6: درهم غير شامل الضريبة, للطرف الثاني مقابل أعمال التصاميم
B7: 3 | C7: يلتزم الطرف الأول بدفع كافة رسوم الجهات الحكومية أو الخاصة، والمطلوبة لفتح معاملات اعتماد المخططات والرسومات الهندسية، أو التعديل عليها.
B8: 4 | C8: لا يتحمل الطرف الثاني أي تأخير حاصل من قبل أي جهات أخرى، وتكون حدود مسؤوليته في العمل المنوط به فقط .
B9: 5 | C9: يقر الطرف الأول بأن كل الأفكار و المخططات والتصاميم المقدمة من الطرف الثاني تعتبر حق من حقوق ملكيته الفكرية، ولا يمكن نقلها لأي جهة مهما كانت أو التنازل عنها إلا بكتاب خطي موقع ومختوم من الطرف الثاني.
B10: 6 | C10: أي مبالغ مدفوعة في أي مرحلة من مراحل تصميم المشروع والإشراف عليه، تكون نظير للأفكار والجهد والوقت والخدمة المقدمة من قبل الطرف الثاني، ولا يعطي الحق للطرف الأول في المطالبة باسترجاع تلك المبالغ في حال عدم إكماله للمشروع.
B11: 7 | C11: يستحق الطرف الثاني نسبة من القيمة الإجمالية لعقد المقاولة ، يدفعه مقاول المشروع، أو الطرف الأول.
B12: 8 | C12: يلتزم الطرف الأول بدفع مبلغ مقابل إشراف | H12: =المدخلات!$P$10 -> 0 | I12: درهم،غير شامل الضريبة وتكون مستحقة بداية كل شهر ميلادي من بداية تنفيذ المشروع وحتى الانتهاء من إنجازه.
B13: 9 | C13: يلتزم الطرف الثاني بأن تكون الزيارات الإشرافية بمعدل أربع زيارات في الشهر تحسب بمعدل إجمالي طيلة فترة تنفيذ المشروع، وحسب ما يقتضيه تقدم الأشغال في الموقع، كما يقر الطرف الثاني أنه في حال توقف الأشغال لمدة ثلاثة أشهر أو أكثر لأي سبب كان، فأنه لا يحق له مطالبة الطرف الأول بدفع مبلغ الإشراف في فترة التوقف.
B14: 10 | C14: اذا وجد عائق من عوائق الارض ( ديفان , كابل كهرباء , تعديل تحت المنسوب….) فالطرف الاول من يتحمل تسوية الموضوع.
B15: 11 | C15: يلتزم المالك بدفع رسوم إضافية يحددها الاستشاري فب حال طلب المالك أي تعديل علي المخططات بعد البدء بتجهيز المخططات التنفيذية لاعتمادها من الجهات الحكومبة و ينطبق ذلك علي أي تعديلات لاحقة
B16: 12 | C16: يلتزم المالك بدفع رسوم معاملة ادخال الكهرباء و معاملة الإنجاز في اخر المشروع
B17: 13 | C17: يحق للطرف الثاني (الاستشاري) نشر صور وفيديوات للمشروع
B18: 14 | C18: يحق للطرف الأول تغيير الطرف الثاني (الاستشاري) أثناء تنفيذ مشروع البناء، وليس قبل ذلك بأي حال من الأحوال ،و في حال الطرف الاول قرر عدم مواصلة المشروع قبل مرحلة التنفيذ يلتزم بدفع باقي المبالغ المستحقة و يكون المبلغ المدفوع في البند 2 نظير اعمال التصاميم المبدئية فقط مع الاحتفاظ بحقوق التصميم.
B19: 15
B20: المالك | H20: الاستشاري
B21: =المدخلات!$P$3 -> احمد ابراهيم النعيمي | H21: سافانا ديزاين للاستشارات الهندسية والتصميم الداخلي

Sheet أسعار التوريد
B1: المالك | G1: =[1]المدخلات!P3 -> محمد ناصر المنصوري | S1: المنطفة | Y1: =[1]المدخلات!AR3 -> Awafi | AG1: القسيمة | AM1: =[1]المدخلات!AR4 -> 406131934 | AU1: المقاول | AY1: =[1]المدخلات!AR10 -> السفير
B2: ='[1]حساب الكميات'!AO277 -> 0
B3: اختيار الأنواع
J4: 1 | K4: السخان | R4: مركزي مع 2 سخان Ariston 200 L | AD4: 15- خزان استرجاع مياه التكييف | AT4: تحت الأرض
J5: 2 | K5: كراسي الحمامات | R5: عادي | AD5: 16- مكسرات المغاسل والحمامات | AT5: عادية
J6: 3 | K6: الشفط | R6: مركزي مخفي للسطح او للجدران الخارجية | AD6: 17- الصرف | AT6: كلين اوت
J7: 4 | K7: النعلة | R7: شامل النعلات - مخفية | AD7: 18-حبات السيراميك | AT7: متوسطة
P8: 5-الألمنيوم | R8: بروفايل فول امبريلا عادي | AD8: 19- سعة خزان المياه | AT8: 1000 جالون
P9: 6- خزان المياه | R9: فوق الأرض | AD9: 20- ارتفاعات الأبواب | AT9: 250 Cm
P10: 7-الباب الرئيسي كاست المنيوم | R10: دبل هايت | AD10: 21-نقاط مياه في السور: | AT10: عدد 4
P11: 8-نوع الصبغ: | R11: سانديكس | AD11: 22-نقاط كهرباء في السور: | AT11: 4
P12: 9-الماء الحار والبارد للشطاف : | R12: كامل حمامات البيت | AD12: 23- الحجر والبورسلان الخارجي: | AT12: 50
P13: 10-نقطة كهرباء سيارة: | R13: لا | AD13: 24- نقاط الكاميرا: | AT13: 6
P14: 11-نقاط اضاءة بالواجهة | R14: نعم | AD14: 25- سعر سيراميك الملاحق: | AT14: 30
P15: 12-نقطة صرف وتغذية للبانتري في الدور الأول: | R15: نعم | AD15: 26-أحواض الزراعة: | AT15: يوجد
P16: 13-نقطة مياه السطح: | R16: 1 | AD16: 27-نعلة مخفية للجبس بلاستر | AT16: يوجد
P17: 14-نقطة كهرباء في السطح: | R17: 1 | AD17: 28-مدة التعاقد | AT17: 16 شهر
B18: 03-الطابوق | R18: =[1]Sheet2!B126 -> راكنور | AD18: 02-الخرسانة | AT18: =[1]Sheet2!B130 -> الخليج
R19: =[1]Sheet2!B127 -> راس الخيمة | AT19: =[1]Sheet2!B131 -> النعيمي
AT20: =[1]Sheet2!B132 -> اوريميكس
B21: 31- تركيب تمديدات التغذية فوق السطح | R21: علي جدران البارابت | AD21: 32-صرف الحمامات الدور الاول | AT21: =[1]Sheet2!B141 -> داكت من تحت لفوق السطح
AT22: =[1]Sheet2!B142 -> تحت الاسقف الي داكت الارضي
B23: 33-نوعية بايبات و اسلاك الكهرباء | R23: ناشيونال | AD23: 34-نوعية تمديدات تغذية المياه | AT23: =[1]Sheet2!B147 -> اكواثرم
AT24: =[1]Sheet2!B148 -> راكثيرم
B25: 35-نوعية بايبات الصرف الصحي | R25: اطلس | AD25: 36-مراوح الشفاط المركزي | AT25: اعمال مدنية بايبات على المقاول
B26: 37-قواطع بانواعها | R26: شنايدر | AD26: 38-اللوحات و الصناديق | AT26: شنايدر
B27: 39-الايزوليتر | R27: شنايدر | AD27: 40-مفاتيح الانارة | AT27: ليجراند
B28: 41-اعمال مدنية للتكييف | R28: مركزي او سبليت علي المقاول | AD28: 42-تجويفات جدران الحمامات | AT28: جدار واحد حسب الديكور عمق 13 سنت
B29: 43-الدرج الامامي لمدخل الفيلا | R29: طاير مع اضاءة من تحت | AD29: 44-تركيب قروفات بالسور | AT29: توريد مالك تركيب مقاول
B30: 45-حماية الارضيات بعد تركيب البورسلان | R30: طبقة جبس مع بلاستيك | AD30: 46-توريد و تركيب رداد للكلين اوت | AT30: من ضمن السعر
B31: 47- جي اي بوكس للماخذ و المفاتيح | R31: الفنار | AD31: 01-الحديد | AT31: قطري
B33: المشرووع | S33: القسيممة | Y33: المنطقة | AG33: المقاول | AS33: المالك
B34: =المدخلات!$P$4 -> فيلا دور أرضي و اول وسور | S34: =المدخلات!$P$12 -> 403100010 | Y34: =المدخلات!$P$11 -> الخران | AG34: =المدخلات!$AR$3 -> 0 | AS34: =المدخلات!$P$3 -> احمد ابراهيم النعيمي
B37: أسعار توريد التشطيبات
B39: البند | AR39: الوحدة | AW39: سعر التوريد
B41: اسعار توريد السيراميك | R41: ='حساب الكميات'!F133 -> اكساءات ارضيات للمدخل الرئيسي للفيلا | AR41: M2 | AW41: 50
R42: ='حساب الكميات'!F134 -> أرضيات درج المدخل الرئيسي والرامب | AR42: M2 | AW42: 80
R43: ='حساب الكميات'!F135 -> أرضيات التيراس بالدور الاول ان وجد | AR43: M2 | AW43: 50
R44: ='حساب الكميات'!F136 -> اكساءات ارضيات الدور الاول و الارض | AR44: M2 | AW44: 35
R45: ='حساب الكميات'!F137 -> اكساء الدرج الداخلي للفيلا. | AR45: L.M | AW45: 250
...

Sheet المواصفات الفنية
A10: المواصفات الفنية والشروط العامة
A16: مشروع | Z16: =المدخلات!P4 -> فيلا دور أرضي و اول وسور
A18: عايدة للمالك | Z18: =المدخلات!P3 -> احمد ابراهيم النعيمي
M22: القسيمة | Z22: =المدخلات!$P$12 -> 403100010
M26: المنطقة | Z26: =المدخلات!$P$11 -> الخران
A34: فهرس دفتر الشروط الفنية الخاصة
A36: ( 1 ) المتطلبات العامة وأعمال تحضير الموقع
A37: ( 2 ) أعمال الحفر والرودبيس
A38: ( 3 ) أعمال الخرسانات
A39: ( 4 ) أعمال الطابوق
A40: ( 5 ) أعمال البلاستر
A41: ( 6 ) أعمال العزل
A42: ( 7 ) الأعمال الصحية
A43: ( 8 ) الأعمال الكهربائية
A44: ( 9 ) أعمال الهاندريل والألمنيوم والزجاج
A45: ( 10 ) جدول تشطيبات الأعمال الصحية
A46: ( 11 ) جدول تشطيبات الأعمال الكهربائية
... A65: 2.1.1- المشروع والموقع :
A66: ="1 – المطلوب إنشاؤه هو مشروع "&TEXT([2]المدخلات!P4,0)&" "&"على قطعة أرض رقم "&" "&TEXT([2]المدخلات!AR4,0)&" "&"في منطقة"&" "&TEXT([2]المدخلات!AR3,0) -> 1 – المطلوب إنشاؤه هو مشروع فيلا ارضي اول مع تعديل واجهة الملحق على قطعة أرض رقم 412030315 في منطقة مدينة خليفة بن زايد
A67: 2 – يتم تنفيذ جميع الأعمال طبقاً للرسومات والمواصفات المعدة لهذا الغرض من قبل الاستشاري، وكل ماورد في الرسومات أو المواصفات يعتبر مطلوباً من المقاول، وهو جزءاً لايتجزأ من العقد. 3 – على المقاول اتخاذ جميع الاحتياطات اللازمة فيما يتعلق باستخدام الطرق وتوفير عوامل السلامة العامة، ومراعاة أنظمة وتعليمات ومتطلبات الجهات الرسمية المعنية فيما يتعلق بذلك.
A71: 3.1.1- تدقيـق الأعمــال :
A72: على المقاول إعلام الاستشاري مسبقاً والتنسيق معه لأي عمل و/أو جزء من العمل يحتاج إلى تدقيق من الاستشاري قبل المباشرة بتنفيذ ما يتبعه من أعمال على أن يتم إعلام الاستشاري بذلك قبل (24) ساعة على الأقل من الموعد المفترض لتدقيق ذلك العمل.
A76: 4.1.1- الرسومات التنفيذية :
A77: 1 – على المقاول إعداد رسومات تنفيذية مفصلة حيثما ورد ذلك في المواصفات الخاصة لأي عمل من الأعمال، واعتماد تلك الرسومات من الاستشاري أولاً ومن الجهات الرسمية المعنية ( حيث يلزم ذلك ) خطيـاً قبل البدء في التنفيذ، ويتحمل المقاول مسؤولية أية أعمال و/أو مواد يقوم بتوريدها أو تركيبها قبل اعتماد تلك الرسومات. 2 – على المقاول تقديم ثلاث نسخ من الرسومات التنفيذية/الرسومات التنفيذية المعدلة للأعمال كما تم تنفيذها على أرض الواقـع (As Built Drawings) قبل موعد الاستلام الابتدائي للمشروع.
A83: 5.1.1- الخدمات القائمة :
A84: على المقاول المحافظة على سلامة الخدمات الموجودة داخل وحول الموقع والتي لاتقع ضمن دائرة الأعمال المطلوبة منه، ويتحمل المقاول المسؤولية والتكاليف المترتبة، عند الإخلال بذلك، لإعادة الوضع إلى ما كان عليه لتلك الخدمات واستبدال التالف منها بمثله دون المطالبة بأي تعويض نظير ذلك ( والتنسيق مع الجهات المعنية فيما يتعلق بتحويل تلك الخدمات )، بما يشمل وضع الطريق والأرصفة المحيطة.
A90: 5.1.1- الخدمات القائمة :
A91: على المقاول المحافظة على سلامة الخدمات الموجودة داخل وحول الموقع والتي لاتقع ضمن دائرة الأعمال المطلوبة منه، ويتحمل المقاول المسؤولية والتكاليف المترتبة، عند الإخلال بذلك، لإعادة الوضع إلى ما كان عليه لتلك الخدمات واستبدال التالف منها بمثله دون المطالبة بأي تعويض نظير ذلك ( والتنسيق مع الجهات المعنية فيما يتعلق بتحويل تلك الخدمات )، بما يشمل وضع الطريق والأرصفة المحيطة.
A96: 2.1-إدارة وتنظيم موقع العمل:
A97: 1.2.1- الكادر الفني وموظفو المقاول:
A98: على المقاول تزويد الموقع بالكوادر الفنية والعمالة اللازمة لتنفيذ المشروع بالمستوى المطلوب مع مراعاة مايلي : 1 – جميع عناصر الكادر الفني والعمالة الفنية يجب أن يكونوا من المؤهلين ومن ذوي الخبرة والكفاءة كلاً حسب اختصاصه وحسب متطلبات العمل والتنفيذ ( من حيث العدد والتوزيع ). 2- يتم اعتماد الكوادر الفنية من قبل الاستشاري قبل مباشرتهم للعمل، ويجب أن تكون الكوادر الفنية من ذوي الخبرة بأعمال مماثلة. 3 – يحق للإستشاري الطلب من المقاول إبعاد/استبدال أي شخص مستخدم من قبله إذا رأى الاستشاري أن ذلك الشخص ليس بالمستوى المطلوب من حيث السلوك أو الخبرة لتنفيذ الأعمال. 4 – على المقاول تقديم جدول بأعداد العمالة العادية والفنية العاملة في الموقع بشكل أسبوعي. 5 – يشتمل الكادر الفني (المطلوب من المقاول توفيره كحد أدنى) على : • مدير للمشروع. • مهندس موقع ( Site Engineer )مسؤول عن تنفيذ المشروع للتعامل مع الاستشاري • مراقب فني (Forman) لكل نوع من أنواع الأعمال. • أي كوادر فنية أخرى يطلبها الاستشاري ويرى أنها لازمة لتنفيذ المشروع بالمستوى المطلوب. • مقاول باطن اعمال الالكتروميكانيك يجب ان يكون معتمد من الاستشاري و الـ FEWA.
... A273: وعليه تم التوقيع والإتفاق
A275: المالك | S275: الاستشاري | AL275: المقاول
A276: =المدخلات!$P$3 -> احمد ابراهيم النعيمي | S276: سافانا ديزاين للاستشارات الهندسية | AL276: =المدخلات!$AR$3 -> 0

Sheet المواصفات الفنية2
A10: المواصفات الفنية والشروط العامة
A16: ="لمشروع :"&" "&TEXT(المدخلات!P4,0) -> لمشروع : فيلا دور أرضي و اول وسور
A18: ="عائدة للمالك : السيد /"&" "&TEXT(المدخلات!P3,0) -> عائدة للمالك : السيد / احمد ابراهيم النعيمي
A20: ="والكائن في إمارة"&" "&TEXT(المدخلات!AR6,0)&" في منطقة "&TEXT(المدخلات!AR3,0)&" "&"على القسيمة رقم"&" "&TEXT(المدخلات!AR4,0) -> والكائن في إمارة 0 في منطقة 0 على القسيمة رقم 0
A34: فهرس دفتر الشروط الفنية الخاصة
A36: ( 1 ) المتطلبات العامة وأعمال تحضير الموقع
A37: ( 2 ) أعمال الحفر والرودبيس
A38: ( 3 ) أعمال الخرسانات
A39: ( 4 ) أعمال الطابوق
A40: ( 5 ) أعمال البلاستر
A41: ( 6 ) أعمال العزل
A42: ( 7 ) الأعمال الصحية
A43: ( 8 ) الأعمال الكهربائية
A44: ( 9 ) أعمال الهاندريل والألمنيوم والزجاج
A45: ( 10 ) جدول تشطيبات الأعمال الصحية
A46: ( 11 ) جدول تشطيبات الأعمال الكهربائية
... A65: 2.1.1- المشروع والموقع :
A66: ="1 – المطلوب إنشاؤه هو مشروع "&TEXT(المدخلات!P4,0)&" "&"على قطعة أرض رقم "&" "&TEXT(المدخلات!AR4,0)&" "&"في منطقة"&" "&TEXT(المدخلات!AR3,0) -> 1 – المطلوب إنشاؤه هو مشروع فيلا دور أرضي و اول وسور على قطعة أرض رقم 0 في منطقة 0
A67: 2 – يتم تنفيذ جميع الأعمال طبقاً للرسومات والمواصفات المعدة لهذا الغرض من قبل الاستشاري، وكل ماورد في الرسومات أو المواصفات يعتبر مطلوباً من المقاول، وهو جزءاً لايتجزأ من العقد. 3 – على المقاول اتخاذ جميع الاحتياطات اللازمة فيما يتعلق باستخدام الطرق وتوفير عوامل السلامة العامة، ومراعاة أنظمة وتعليمات ومتطلبات الجهات الرسمية المعنية فيما يتعلق بذلك.
A71: 3.1.1- تدقيـق الأعمــال :
A72: على المقاول إعلام الاستشاري مسبقاً والتنسيق معه لأي عمل و/أو جزء من العمل يحتاج إلى تدقيق من الاستشاري قبل المباشرة بتنفيذ ما يتبعه من أعمال على أن يتم إعلام الاستشاري بذلك قبل (24) ساعة على الأقل من الموعد المفترض لتدقيق ذلك العمل.
A76: 4.1.1- الرسومات التنفيذية :
A77: 1 – على المقاول إعداد رسومات تنفيذية مفصلة حيثما ورد ذلك في المواصفات الخاصة لأي عمل من الأعمال، واعتماد تلك الرسومات من الاستشاري أولاً ومن الجهات الرسمية المعنية ( حيث يلزم ذلك ) خطيـاً قبل البدء في التنفيذ، ويتحمل المقاول مسؤولية أية أعمال و/أو مواد يقوم بتوريدها أو تركيبها قبل اعتماد تلك الرسومات. 2 – على المقاول تقديم ثلاث نسخ من الرسومات التنفيذية/الرسومات التنفيذية المعدلة للأعمال كما تم تنفيذها على أرض الواقـع (As Built Drawings) قبل موعد الاستلام الابتدائي للمشروع.
A83: 5.1.1- الخدمات القائمة :
A84: على المقاول المحافظة على سلامة الخدمات الموجودة داخل وحول الموقع والتي لاتقع ضمن دائرة الأعمال المطلوبة منه، ويتحمل المقاول المسؤولية والتكاليف المترتبة، عند الإخلال بذلك، لإعادة الوضع إلى ما كان عليه لتلك الخدمات واستبدال التالف منها بمثله دون المطالبة بأي تعويض نظير ذلك ( والتنسيق مع الجهات المعنية فيما يتعلق بتحويل تلك الخدمات )، بما يشمل وضع الطريق والأرصفة المحيطة.
A90: 5.1.1- الخدمات القائمة :
A91: على المقاول المحافظة على سلامة الخدمات الموجودة داخل وحول الموقع والتي لاتقع ضمن دائرة الأعمال المطلوبة منه، ويتحمل المقاول المسؤولية والتكاليف المترتبة، عند الإخلال بذلك، لإعادة الوضع إلى ما كان عليه لتلك الخدمات واستبدال التالف منها بمثله دون المطالبة بأي تعويض نظير ذلك ( والتنسيق مع الجهات المعنية فيما يتعلق بتحويل تلك الخدمات )، بما يشمل وضع الطريق والأرصفة المحيطة.
A96: 2.1-إدارة وتنظيم موقع العمل:
A97: 1.2.1- الكادر الفني وموظفو المقاول:
A98: على المقاول تزويد الموقع بالكوادر الفنية والعمالة اللازمة لتنفيذ المشروع بالمستوى المطلوب مع مراعاة مايلي : 1 – جميع عناصر الكادر الفني والعمالة الفنية يجب أن يكونوا من المؤهلين ومن ذوي الخبرة والكفاءة كلاً حسب اختصاصه وحسب متطلبات العمل والتنفيذ ( من حيث العدد والتوزيع ). 2- يتم اعتماد الكوادر الفنية من قبل الاستشاري قبل مباشرتهم للعمل، ويجب أن تكون الكوادر الفنية من ذوي الخبرة بأعمال مماثلة. 3 – يحق للإستشاري الطلب من المقاول إبعاد/استبدال أي شخص مستخدم من قبله إذا رأى الاستشاري أن ذلك الشخص ليس بالمستوى المطلوب من حيث السلوك أو الخبرة لتنفيذ الأعمال. 4 – على المقاول تقديم جدول بأعداد العمالة العادية والفنية العاملة في الموقع بشكل أسبوعي. 5 – يشتمل الكادر الفني (المطلوب من المقاول توفيره كحد أدنى) على : • مدير للمشروع. • مهندس موقع ( Site Engineer )مسؤول عن تنفيذ المشروع للتعامل مع الاستشاري • مراقب فني (Forman) لكل نوع من أنواع الأعمال. • أي كوادر فنية أخرى يطلبها الاستشاري ويرى أنها لازمة لتنفيذ المشروع بالمستوى المطلوب. • مقاول باطن اعمال الالكتروميكانيك يجب ان يكون معتمد من الاستشاري و الـ FEWA.
... A273: وعليه تم التوقيع والإتفاق
A275: المالك | S275: الاستشاري | AL275: المقاول
A276: =المدخلات!P3 -> احمد ابراهيم النعيمي | S276: سافانا ديزاين للاستشارات الهندسية | AL276: =المدخلات!$AR$10 -> 0

Sheet عقد جديد 
A1: عقد الاتفاق Agreement
A3: بإشرافنا نحن
A4: سافانا ديزاين للإستشارات الهندسية والتصميم الداخلي- رأس الخيمة
A6: مكتب 407 أبراج جلفار رأس الخيمة
A7: 525015080
A9: تم الاتفاق بين كل من
A10: الطرف الاول | B10: المالك | D10: =المدخلات!$P$3 -> احمد ابراهيم النعيمي
A11: الطرف الثاني | B11: =المدخلات!AD10 -> 0 | D11: =المدخلات!$AR$10 -> 0
A12: الطرف الثالث | B12: ( الاستشاري) | D12: سافانا ديزاين للاستشارات الهندسية
A14: المشروع
A15: وصف المشروع | D15: =المدخلات!$P$4 -> فيلا دور أرضي و اول وسور
A16: المنطقة | D16: =المدخلات!$AR$3 -> 0
A17: رقم القسيمة | D17: =المدخلات!AR4 -> 0
A19: ='[3]حساب الكميات'!AO270 -> سعر الفيلا مع السور(بدون الضريبة)
A21: يقوم الطرف الثاني بتنفيذ وانشاء وانجاز وصيانة المشروع المذكور اعلاه لقاء مبلغ وقدره
A22: اماراتي فقط بدون الضريبة مليون و مئة و ثمانون الف درهم
A23: و ذلك حسب المتفق عليه والمعتمد وفق للمناقصة التي جرت
A25: توقيع وختم المقاول | D25: توقيع وختم المالك | G25: توقيع وختم الاستشاري
A32: بنود العقد
A34: كافة مستندات المشروع و جميع متعلقاته متكاملة فيما بينها و تشمل المشروع ككل أي بحال عدم ذكر اي بند بالمواصفات او المخططات وتم ذكره بجدول الكميات او المخططات المعتمدة أو اي مستند اخر غير ذلك , والعكس صحيح على المقاول الالتزام به و العمل على تضمينه بأعمال المشروع اينما ذكر .علي المقاول ارجاع العقد موقع علي كل صفحة والمواصافات و المخططات وتوقيعه عليها يعتبر انه اطلع علي جميع تفاصيل المشروع
A36: 1 | B36: الاطلاع علي جميع مخططات المشروع | I36: =A36 -> 1
A37: على المقاول قبل توقيع العقد الاطلاع على المخططات و المواصفات و الشروط و التأكد من تطابق جميع المخططات الانشائية والمعمارية والخدمات و المناظير 3D وتنبيه الاستشاري لأي اختلاف في تطابق المخططات وذلك لتفادي التغيير و التعديل في الموقع قبل التنفيذ و في حالة عدم تنبيه الاستشاري بوجود اختلاف قبل الشروع في العمل يتحمل المقاول كامل المسؤولية في التعديلات المطلوبة و التاخير المترتب عن ذلك و اعتبار أن توقيعه عليها يعني موافقته على جميع ما ورد بها وتعتبر المناظير المقدمة من الاستشاري في ملف المناقصة هي المعتمدة من ناحية الشكل و التشطيبات في حال اختلاف مع المخططات المعتمدة .
B38: إصدار التعليمات, الرسوم | D38: إصدار التعليمات, الرسوم
A39: لا يحق للمالك اصدار اي تعليمات للمقاول تتعلق بتنفيذ المشروع الا عن طريق الاستشاري
A40: 2 | B40: مقاولي الباطن | G40: 2 | I40: =A40 -> 2
A41: يجوز للطرف الثاني اسناد جزء من الاعمال الى مقاولي الباطن المعتمدين والمسجلين لدى البلدية بموجب موافقة خطية من الاستشاري
A42: يكون المقاول مسؤول مسؤولية كاملة عن اعمال المقاول الباطن من حيث الجودة والتنفيذ واصول الصناعه والضمانات
A43: يتعهد الطرف الثاني بالتنسيق بين جميع المقاولين الباطن دون اي استثناء ودون اي احقية في المطالبة باي مبلغ اضافة نظير ذلك.
A45: 3 | B45: فسخ التعاقد | G45: 3 | I45: =A45 -> 3
A46: يحق للمهندس الاستشاري فسخ العقد في الحالات
A47: اذا تاخر المقاول عن بدء الاعمال بعد تسليم الموقع
A48: اذا تاخر المقاول في اتمام العمل وتسليمه في المواعيد المحدده لكل مرحلة في الجدول الزمني المعتمد
A49: اذا اظهر المقاول بطئا في سير العمل لدرجة يرى الاستشاري منها عدم قدرة الطرف الثاني على اتمام العمل في موعده على ان يقوم الاستشاري بتنبيه المقاول خطيا .
A50: اذا اخل المقاول ببرنامج العمل المحدد بشكل يؤثر على مستوى التنفيذ او الاخلال بالمواصفات المتفق عليها
A51: اذا انسحب المقاول عن العمل او تركه او افلس
A52: اذا اسند الطرف الثاني العمل لمقاول باطن دون اخطار الاستشاري
A53: في حال تاخير الطرف الاول عن سداد اي من مستحقات الطرف الثاني في موعد اقصاه 30 يوم فمن حق الطرف الثاني التوقف عن العمل وذلك بعد اخطار الاستشاري خطيا وتحسب فتره التاخير على المالك لصالح المقاول كمدة اضافية للمشروع.
A54: يحق للطرف الثاني الغاء التعاقد في حالة تاخير المالك باختيار التشطيبات مما يعود بالضرر علي المقاول
A55: 4 | B55: الاثار المترتبة على فسخ العقد | G55: 4 | I55: =A55 -> 4
A56: حساب غرامة التاخير على الطرف الثاني طبقا للعقد حتى تاريخ ابلاغ المقاول بقرار السحب.
...

Sheet اتفاق  (2)
B1: عقد اتفاق بين المالك و الاستشاري
B2: انه في يوم | F2: =المدخلات!$P$8 -> الاريعاء | K2: بتاريخ | N2: =المدخلات!$P$7 -> 0 | U2: حرر بين كل من:
B4: • | C4: ="الطرف الأول السيد:"&" "&TEXT(المدخلات!P3,0)&" "&"مالك المشروع,قسيمة رقم :"&TEXT(المدخلات!AR4,0)&" منطقة "&TEXT(المدخلات!AR3,0)&" بإمارة رأس الخيمة" -> الطرف الأول السيد: احمد ابراهيم النعيمي مالك المشروع,قسيمة رقم :0 منطقة 0 بإمارة رأس الخيمة
B5: • | C5: الطرف الثاني: شركة سافانا ديزاين للاستشارات الهندسية والتصميم الداخلي، رخصة رقم(48818)، وعنوانها مكتب رقم (407) بأبراج جلفار، في إمارة رأس الخيمة ، ويمثلها المدير / المهندس أيمن بن حمادي، وبعد أن أقر المتعاقدان بأهليتهما للتصرف والتعاقد اتفقا على ما يأتي:
B8: 1 | C8: قبل الطرف الثاني بموجب هذا العقد أن يقوم بأعمال التصميم الهندسي والإشراف عل مشروع الفيلا الخاصة بالطرف الأول، الوارد بياناتها في مقدمة هذا العقد، وذلك حسب المعايير والمواصفات المحددة من قبل الجهات المختصة.
B10: 2 | C10: ="يلتزم الطرف الأول بدفع مبلغ وقدره "&" "&TEXT(المدخلات!P9,0)&" "&"درهم غير شامل الضريبة, للطرف الثاني مقابل أعمال التصاميم" -> يلتزم الطرف الأول بدفع مبلغ وقدره 0 درهم غير شامل الضريبة, للطرف الثاني مقابل أعمال التصاميم
B11: 3 | C11: يلتزم الطرف الأول بدفع كافة رسوم الجهات الحكومية أو الخاصة، والمطلوبة لفتح معاملات اعتماد المخططات والرسومات الهندسية، أو التعديل عليها.
B13: 4 | C13: لا يتحمل الطرف الثاني أي تأخير حاصل من قبل أي جهات أخرى، وتكون حدود مسؤوليته في العمل المنوط به فقط .
B14: 5 | C14: يقر الطرف الأول بأن كل الأفكار و المخططات والتصاميم المقدمة من الطرف الثاني تعتبر حق من حقوق ملكيته الفكرية، ولا يمكن نقلها لأي جهة مهما كانت أو التنازل عنها إلا بكتاب خطي موقع ومختوم من الطرف الثاني.
B16: 6 | C16: أي مبالغ مدفوعة في أي مرحلة من مراحل تصميم المشروع والإشراف عليه، تكون نظير للأفكار والجهد والوقت والخدمة المقدمة من قبل الطرف الثاني، ولا يعطي الحق للطرف الأول في المطالبة باسترجاع تلك المبالغ في حال عدم إكماله للمشروع.
B18: 7 | C18: يستحق الطرف الثاني نسبة من القيمة الإجمالية لعقد المقاولة ، يدفعه مقاول المشروع، أو الطرف الأول.
B19: 8 | C19: ="يلتزم الطرف الأول بدفع مبلغ مقابل إشراف الطرف الثاني على تنفيذ المشروع، وتدفع كمبلغ مقطوع و على دفعات ثابتة قيمتها" &" "&TEXT(المدخلات!P10,0)&"درهم،غير شامل الضريبة وتكون مستحقة بداية كل شهر ميلادي من بداية تنفيذ المشروع وحتى الانتهاء من إنجازه." -> يلتزم الطرف الأول بدفع مبلغ مقابل إشراف الطرف الثاني على تنفيذ المشروع، وتدفع كمبلغ مقطوع و على دفعات ثابتة قيمتها 0درهم،غير شامل الضريبة وتكون مستحقة بداية كل شهر ميلادي من بداية تنفيذ المشروع وحتى الانتهاء من إنجازه.
B22: 9 | C22: يلتزم الطرف الثاني بأن تكون الزيارات الإشرافية بمعدل أربع زيارات في الشهر تحسب بمعدل إجمالي طيلة فترة تنفيذ المشروع، وحسب ما يقتضيه تقدم الأشغال في الموقع، كما يقر الطرف الثاني أنه في حال توقف الأشغال لمدة ثلاثة أشهر أو أكثر لأي سبب كان، فأنه لا يحق له مطالبة الطرف الأول بدفع مبلغ الإشراف في فترة التوقف.
B24: 10 | C24: اذا وجد عائق من عوائق الارض ( ديفان , كابل كهرباء , تعديل تحت المنسوب….) فالطرف الاول من يتحمل تسوية الموضوع.
B25: 11 | C25: يلتزم المالك بدفع رسوم إضافية يحددها الاستشاري فب حال طلب المالك أي تعديل علي المخططات بعد البدء بتجهيز المخططات التنفيذية لاعتمادها من الجهات الحكومبة و ينطبق ذلك علي أي تعديلات لاحقة
B26: 12 | C26: يلتزم المالك بدفع رسوم معاملة ادخال الكهرباء و معاملة الإنجاز في اخر المشروع
B27: 13 | C27: يحق للطرف الثاني (الاستشاري) نشر صور وفيديوات للمشروع
B28: 14 | C28: يحق للطرف الأول تغيير الطرف الثاني (الاستشاري) أثناء تنفيذ مشروع البناء، وليس قبل ذلك بأي حال من الأحوال ،و في حال الطرف الاول قرر عدم مواصلة المشروع قبل مرحلة التنفيذ يلتزم بدفع باقي المبالغ المستحقة و يكون المبلغ المدفوع في البند 2 نظير اعمال التصاميم المبدئية فقط مع الاحتفاظ بحقوق التصميم.
A32: يقر الطرفان على اطلاعهما وموافقتهما على كل ما ورد في هذا العقد وعليه يوقعان
A35: المالك | Z35: الاستشاري
A36: =المدخلات!$P$3 -> احمد ابراهيم النعيمي | Z36: سافانا ديزاين للاستشارات الهندسية والتصميم الداخلي

Sheet حساب الكميات (2)
B2: حساب كميات المشروع
B3: معلومات المشروع
B4: المالك | K4: =المدخلات!$P$3 -> احمد ابراهيم النعيمي | AD4: المنطقة | AQ4: =المدخلات!$AR$3 -> 0
B5: وصف المشروع | K5: =المدخلات!$P$4 -> فيلا دور أرضي و اول وسور | AD5: رقم القسيمة | AQ5: =المدخلات!$AR$4 -> 0
B6: مساحة السور م.طولي | K6: =المدخلات!AR5 -> 118 | AD6: مساحة البناء بالقدم المربع | AQ6: =المدخلات!$AY$5 -> 5549
B7: #VALUE!
B24: بيانات المقاول
B25: اسم الشركة | F25: Contra name | K25: العزة لمقاولات البناء | AD25: المهندس | AI25: Engineer
B26: تاريخ | E26: Date | AD26: رقم الهاتف: | AI26: Phone No
B27: License number | AD27: مدة تنفيذ | AI27: Construction period | AQ27: =المدخلات!$AR$9 -> 14 شهر
B29: عرض السعر / Price OFFER | AQ29: ختم الشركة العارضة / Contractor Stamp
B30: تكلفة انشاء وانجاز الفيلا | P30: Total villa cost | AD30: =AO236 -> #VALUE! | AQ30: =المدخلات!AR10 -> 0
B31: تكلفة انشاء وإنجاز السور | P31: Total Boundary wall cost | AD31: =AY231 -> 0
B32: تكلفة انشاء وإنجاز الفيلا مع السور | P32: Total Villa and Boundary wall | AD32: =AD30+AD31 -> #VALUE!
B33: الضريبة | P33: VAT | AD33: =AD32*0.05 -> #VALUE!
B34: القيمة الاجمالية للمشروع شامل الضريبة | P34: Total project value with Vat | AD34: =AD32+AD33 -> #VALUE!
B36: السعر المقدم بعد دراسة جميع بنود العقد والمواصفات ومطابقة جميع المخططات ومناظير ال 3D والموافقة عليها | AI36: The prices should include all contract activities m specification , confirming all drawings with project 3d
B37: حساب الكميات يجب ان يكون دقيق وان لا تتعدا الكميات 5% | AI37: Bill of Quantities should be accurate and not pass 5%
B38: علي المقاول الاستفسار من الاستشاري عن كل بند لم يكن واضحا في المناقصة . | AI38: contractor should send queries to consultant for any item not clear in the tender
B40: أولا : اعـــــمـــــــــال الـــــهــــيكــــــل | C40: أولا : أعمال الهيكل | AI40: english
C41: A | F41: أعمال المياه الجوفية و إحلال التربة وتجهز الموقع
C42: A1 | F42: تجفيف المياه الجوفية | Y42: Dewatering | AO42: L.S | AP42: M2 | AQ42: M2 | AR42: M2 | AS42: 0 | AW42: 2 | BA42: =AW42*AS42 -> 0
C43: A2 | F43: إحلال التربة | Y43: Soil replacement | AO43: L.S | AP43: M2 | AQ43: M2 | AR43: M2 | AS43: 0 | AW43: 2 | BA43: =AW43*AS43 -> 0
C44: A3 | F44: تجهيز الموقع | Y44: Mobilization | AO44: L.S | AP44: M2 | AQ44: M2 | AR44: M2 | AS44: 1 | AW44: 15000 | BA44: =AW44*AS44 -> 15000
C45: المياه الجوفية و إحلال التربة وتجهز الموقع | Y45: dewatering , soil replacement and Mobilization | AO45: =SUM(BA42:BD44) -> 15000
C46: B | F46: أعمال تحت منسوب الأرض | AO46: substructure works
C47: B1 | F47: الحفر | X47: Excavation | AO47: M3 | AP47: M2 | AQ47: M2 | AR47: M2 | AS47: 700 | AW47: 9 | BA47: =AW47*AS47 -> 6300
C48: B2 | F48: الرودبيس | X48: Road base | AO48: M3 | AP48: M2 | AQ48: M2 | AR48: M2 | AS48: 130 | AW48: 30 | BA48: =AW48*AS48 -> 3900
C49: B3 | F49: خرسانة أسفل القواعد | X49: PCC under foundation | AO49: M3 | AP49: M2 | AQ49: M2 | AR49: M2 | AS49: 17 | AW49: 400 | BA49: =AW49*AS49 -> 6800
C50: B4 | F50: خرسانة للقواعد | X50: RCC Foundation | AO50: M3 | AP50: M2 | AQ50: M2 | AR50: M2 | AS50: 93 | AW50: 950 | BA50: =AW50*AS50 -> 88350
C51: B5 | F51: خرسانة مسلحة رقاب أعمدة | X51: Neck Columns | AO51: M3 | AP51: M2 | AQ51: M2 | AR51: M2 | AS51: 3 | AW51: 1300 | BA51: =AW51*AS51 -> 3900
C52: B6 | F52: طابوق مصمت أسفل الجسور الأرضية | X52: Solid block under tie beams | AO52: M2 | AS52: 135 | AW52: 85 | BA52: =AW52*AS52 -> 11475
C53: B7 | F53: الجسور الأرضية | X53: Tie beams | AO53: M3 | AS53: 19 | AW53: 950 | BA53: =AW53*AS53 -> 18050
C54: B8 | F54: عزل تحت منسوب الارض | X54: water proof for substructure | AO54: L.S | AS54: 1 | AW54: 5000 | BA54: =AW54*AS54 -> 5000
C55: B9 | F55: لوحات البولي ايثيلين | X55: Polythene sheet | AO55: L.S | AS55: 1 | AW55: 2500 | BA55: =AW55*AS55 -> 2500
C56: B10 | F56: الدفان والدمك | X56: back filling and compaction | AO56: M3 | AS56: 600 | AW56: 25 | BA56: =AW56*AS56 -> 15000
C57: B11 | F57: الخرسانة الأرضية | X57: Flooring | AO57: M3 | AS57: 27.5 | AW57: 425 | BA57: =AW57*AS57 -> 11687.5
C58: B12 | F58: معالجة النمل الأبيض (مرتين) | X58: Ant termite | AO58: L.S | AS58: 1 | AW58: 1700 | BA58: =AW58*AS58 -> 1700
C59: B13 | F59: غرفة المياه تحت الأرض | X59: Under ground water tank | AO59: L.S | AS59: 1 | AW59: 8000 | BA59: =AW59*AS59 -> 8000
C60: B14 | F60: غرفة استرجاع مياه التكييف تحت الأرض | X60: under ground tank for AC water | AO60: L.S | AS60: 1 | AW60: 8000 | BA60: =AW60*AS60 -> 8000
...

Sheet المواصفات الفنية (2)
A10: المواصفات الفنية والشروط العامة
A16: مشروع | Z16: =المدخلات!P4 -> فيلا دور أرضي و اول وسور
A18: عايدة للمالك | Z18: =المدخلات!P3 -> احمد ابراهيم النعيمي
M22: القسيمة | Z22: =المدخلات!AR4 -> 0
M26: المنطقة | Z26: =المدخلات!AR3 -> 0
A34: فهرس دفتر الشروط الفنية الخاصة
A36: ( 1 ) المتطلبات العامة وأعمال تحضير الموقع
A37: ( 2 ) أعمال الحفر والرودبيس
A38: ( 3 ) أعمال الخرسانات
A39: ( 4 ) أعمال الطابوق
A40: ( 5 ) أعمال البلاستر
A41: ( 6 ) أعمال العزل
A42: ( 7 ) الأعمال الصحية
A43: ( 8 ) الأعمال الكهربائية
A44: ( 9 ) أعمال الهاندريل والألمنيوم والزجاج
A45: ( 10 ) جدول تشطيبات الأعمال الصحية
A46: ( 11 ) جدول تشطيبات الأعمال الكهربائية
... A65: 2.1.1- المشروع والموقع :
A66: ="1 – المطلوب إنشاؤه هو مشروع "&TEXT([2]المدخلات!P4,0)&" "&"على قطعة أرض رقم "&" "&TEXT([2]المدخلات!AR4,0)&" "&"في منطقة"&" "&TEXT([2]المدخلات!AR3,0) -> 1 – المطلوب إنشاؤه هو مشروع فيلا ارضي اول مع تعديل واجهة الملحق على قطعة أرض رقم 412030315 في منطقة مدينة خليفة بن زايد
A67: 2 – يتم تنفيذ جميع الأعمال طبقاً للرسومات والمواصفات المعدة لهذا الغرض من قبل الاستشاري، وكل ماورد في الرسومات أو المواصفات يعتبر مطلوباً من المقاول، وهو جزءاً لايتجزأ من العقد. 3 – على المقاول اتخاذ جميع الاحتياطات اللازمة فيما يتعلق باستخدام الطرق وتوفير عوامل السلامة العامة، ومراعاة أنظمة وتعليمات ومتطلبات الجهات الرسمية المعنية فيما يتعلق بذلك.
A71: 3.1.1- تدقيـق الأعمــال :
A72: على المقاول إعلام الاستشاري مسبقاً والتنسيق معه لأي عمل و/أو جزء من العمل يحتاج إلى تدقيق من الاستشاري قبل المباشرة بتنفيذ ما يتبعه من أعمال على أن يتم إعلام الاستشاري بذلك قبل (24) ساعة على الأقل من الموعد المفترض لتدقيق ذلك العمل.
A76: 4.1.1- الرسومات التنفيذية :
A77: 1 – على المقاول إعداد رسومات تنفيذية مفصلة حيثما ورد ذلك في المواصفات الخاصة لأي عمل من الأعمال، واعتماد تلك الرسومات من الاستشاري أولاً ومن الجهات الرسمية المعنية ( حيث يلزم ذلك ) خطيـاً قبل البدء في التنفيذ، ويتحمل المقاول مسؤولية أية أعمال و/أو مواد يقوم بتوريدها أو تركيبها قبل اعتماد تلك الرسومات. 2 – على المقاول تقديم ثلاث نسخ من الرسومات التنفيذية/الرسومات التنفيذية المعدلة للأعمال كما تم تنفيذها على أرض الواقـع (As Built Drawings) قبل موعد الاستلام الابتدائي للمشروع.
A83: 5.1.1- الخدمات القائمة :
A84: على المقاول المحافظة على سلامة الخدمات الموجودة داخل وحول الموقع والتي لاتقع ضمن دائرة الأعمال المطلوبة منه، ويتحمل المقاول المسؤولية والتكاليف المترتبة، عند الإخلال بذلك، لإعادة الوضع إلى ما كان عليه لتلك الخدمات واستبدال التالف منها بمثله دون المطالبة بأي تعويض نظير ذلك ( والتنسيق مع الجهات المعنية فيما يتعلق بتحويل تلك الخدمات )، بما يشمل وضع الطريق والأرصفة المحيطة.
A90: 5.1.1- الخدمات القائمة :
A91: على المقاول المحافظة على سلامة الخدمات الموجودة داخل وحول الموقع والتي لاتقع ضمن دائرة الأعمال المطلوبة منه، ويتحمل المقاول المسؤولية والتكاليف المترتبة، عند الإخلال بذلك، لإعادة الوضع إلى ما كان عليه لتلك الخدمات واستبدال التالف منها بمثله دون المطالبة بأي تعويض نظير ذلك ( والتنسيق مع الجهات المعنية فيما يتعلق بتحويل تلك الخدمات )، بما يشمل وضع الطريق والأرصفة المحيطة.
A96: 2.1-إدارة وتنظيم موقع العمل:
A97: 1.2.1- الكادر الفني وموظفو المقاول:
A98: على المقاول تزويد الموقع بالكوادر الفنية والعمالة اللازمة لتنفيذ المشروع بالمستوى المطلوب مع مراعاة مايلي : 1 – جميع عناصر الكادر الفني والعمالة الفنية يجب أن يكونوا من المؤهلين ومن ذوي الخبرة والكفاءة كلاً حسب اختصاصه وحسب متطلبات العمل والتنفيذ ( من حيث العدد والتوزيع ). 2- يتم اعتماد الكوادر الفنية من قبل الاستشاري قبل مباشرتهم للعمل، ويجب أن تكون الكوادر الفنية من ذوي الخبرة بأعمال مماثلة. 3 – يحق للإستشاري الطلب من المقاول إبعاد/استبدال أي شخص مستخدم من قبله إذا رأى الاستشاري أن ذلك الشخص ليس بالمستوى المطلوب من حيث السلوك أو الخبرة لتنفيذ الأعمال. 4 – على المقاول تقديم جدول بأعداد العمالة العادية والفنية العاملة في الموقع بشكل أسبوعي. 5 – يشتمل الكادر الفني (المطلوب من المقاول توفيره كحد أدنى) على : • مدير للمشروع. • مهندس موقع ( Site Engineer )مسؤول عن تنفيذ المشروع للتعامل مع الاستشاري • مراقب فني (Forman) لكل نوع من أنواع الأعمال. • أي كوادر فنية أخرى يطلبها الاستشاري ويرى أنها لازمة لتنفيذ المشروع بالمستوى المطلوب. • مقاول باطن اعمال الالكتروميكانيك يجب ان يكون معتمد من الاستشاري و الـ FEWA.
... A273: وعليه تم التوقيع والإتفاق
A275: المالك | S275: الاستشاري | AL275: المقاول
A276: =[2]المدخلات!P3 -> فهد سليمان الشحي | S276: سافانا ديزاين للاستشارات الهندسية | AL276: =[2]المدخلات!$AR$10 -> القيصر لمقاولات البناء

Sheet أسعار التوريد (2)
B1: المالك | G1: =[1]المدخلات!P3 -> محمد ناصر المنصوري | S1: المنطفة | Y1: =[1]المدخلات!AR3 -> Awafi | AG1: القسيمة | AM1: =[1]المدخلات!AR4 -> 406131934 | AU1: المقاول | AY1: =[1]المدخلات!AR10 -> السفير
B2: ='[1]حساب الكميات'!AO277 -> 0
B3: اختيار الأنواع
J4: 1 | K4: السخان | R4: مركزي مع 2 سخان Ariston 200 L | AD4: 15- خزان استرجاع مياه التكييف | AT4: تحت الأرض
J5: 2 | K5: كراسي الحمامات | R5: عادي | AD5: 16- مكسرات المغاسل والحمامات | AT5: عادية
J6: 3 | K6: الشفط | R6: مركزي مخفي للسطح او للجدران الخارجية | AD6: 17- الصرف | AT6: كلين اوت
J7: 4 | K7: النعلة | R7: شامل النعلات - مخفية | AD7: 18-حبات السيراميك | AT7: متوسطة
P8: 5-الألمنيوم | R8: بروفايل فول امبريلا عادي | AD8: 19- سعة خزان المياه | AT8: 1000 جالون
P9: 6- خزان المياه | R9: فوق الأرض | AD9: 20- ارتفاعات الأبواب | AT9: 250 Cm
P10: 7-الباب الرئيسي كاست المنيوم | R10: دبل هايت | AD10: 21-نقاط مياه في السور: | AT10: عدد 4
P11: 8-نوع الصبغ: | R11: سانديكس | AD11: 22-نقاط كهرباء في السور: | AT11: 4
P12: 9-الماء الحار والبارد للشطاف : | R12: كامل حمامات البيت | AD12: 23- الحجر والبورسلان الخارجي: | AT12: 50
P13: 10-نقطة كهرباء سيارة: | R13: لا | AD13: 24- نقاط الكاميرا: | AT13: 6
P14: 11-نقاط اضاءة بالواجهة | R14: نعم | AD14: 25- سعر سيراميك الملاحق: | AT14: 30
P15: 12-نقطة صرف وتغذية للبانتري في الدور الأول: | R15: نعم | AD15: 26-أحواض الزراعة: | AT15: يوجد
P16: 13-نقطة مياه السطح: | R16: 1 | AD16: 27-نعلة مخفية للجبس بلاستر | AT16: يوجد
P17: 14-نقطة كهرباء في السطح: | R17: 1 | AD17: 28-مدة التعاقد | AT17: 16 شهر
B18: 03-الطابوق | R18: =[1]Sheet2!B126 -> راكنور | AD18: 02-الخرسانة | AT18: =[1]Sheet2!B130 -> الخليج
R19: =[1]Sheet2!B127 -> راس الخيمة | AT19: =[1]Sheet2!B131 -> النعيمي
AT20: =[1]Sheet2!B132 -> اوريميكس
B21: 31- تركيب تمديدات التغذية فوق السطح | R21: علي جدران البارابت | AD21: 32-صرف الحمامات الدور الاول | AT21: =[1]Sheet2!B141 -> داكت من تحت لفوق السطح
AT22: =[1]Sheet2!B142 -> تحت الاسقف الي داكت الارضي
B23: 33-نوعية بايبات و اسلاك الكهرباء | R23: ناشيونال | AD23: 34-نوعية تمديدات تغذية المياه | AT23: =[1]Sheet2!B147 -> اكواثرم
AT24: =[1]Sheet2!B148 -> راكثيرم
B25: 35-نوعية بايبات الصرف الصحي | R25: اطلس | AD25: 36-مراوح الشفاط المركزي | AT25: اعمال مدنية بايبات على المقاول
B26: 37-قواطع بانواعها | R26: شنايدر | AD26: 38-اللوحات و الصناديق | AT26: شنايدر
B27: 39-الايزوليتر | R27: شنايدر | AD27: 40-مفاتيح الانارة | AT27: ليجراند
B28: 41-اعمال مدنية للتكييف | R28: مركزي او سبليت علي المقاول | AD28: 42-تجويفات جدران الحمامات | AT28: جدار واحد حسب الديكور عمق 13 سنت
B29: 43-الدرج الامامي لمدخل الفيلا | R29: طاير مع اضاءة من تحت | AD29: 44-تركيب قروفات بالسور | AT29: توريد مالك تركيب مقاول
B30: 45-حماية الارضيات بعد تركيب البورسلان | R30: طبقة جبس مع بلاستيك | AD30: 46-توريد و تركيب رداد للكلين اوت | AT30: من ضمن السعر
B31: 47- جي اي بوكس للماخذ و المفاتيح | R31: الفنار | AD31: 01-الحديد | AT31: قطري
B33: المالك | G33: =المدخلات!$P$3 -> احمد ابراهيم النعيمي | S33: المنطفة | Y33: =المدخلات!$AR$3 -> 0 | AG33: القسيمة | AM33: =المدخلات!$AR$4 -> 0 | AU33: المقاول
AU34: =المدخلات!AR10 -> 0
B37: أسعار توريد التشطيبات
B39: البند | AR39: الوحدة | AW39: سعر التوريد
B41: اسعار توريد السيراميك | R41: ='حساب الكميات (2)'!F133 -> اكساءات ارضيات للمدخل الرئيسي للفيلا | AR41: M2 | AW41: 50
R42: ='حساب الكميات (2)'!F134 -> أرضيات درج المدخل الرئيسي والرامب | AR42: M2 | AW42: 80
R43: ='حساب الكميات (2)'!F135 -> أرضيات التيراس بالدور الاول ان وجد | AR43: M2 | AW43: 50
R44: ='حساب الكميات (2)'!F136 -> اكساءات ارضيات الدور الاول و الارض | AR44: M2 | AW44: 35
R45: ='حساب الكميات (2)'!F137 -> اكساء الدرج الداخلي للفيلا. | AR45: L.M | AW45: 250
...

Sheet عقد اساسي
A1: عقد الاتفاق Agreement
A3: بإشرافنا نحن
A4: سافانا ديزاين للإستشارات الهندسية والتصميم الداخلي- رأس الخيمة
A6: مكتب 407 أبراج جلفار رأس الخيمة
A7: 525015080
A9: تم الاتفاق بين كل من
A10: الطرف الاول | B10: المالك | D10: =المدخلات!$P$3 -> احمد ابراهيم النعيمي
A11: الطرف الثاني | B11: المقاول | D11: =المدخلات!$AR$3 -> 0
A12: الطرف الثالث | B12: ( الاستشاري) | D12: سافانا ديزاين للاستشارات الهندسية
A14: المشروع
A15: وصف المشروع | D15: =المدخلات!$P$4 -> فيلا دور أرضي و اول وسور
A16: المنطقة | D16: =المدخلات!$P$11 -> الخران
A17: رقم القسيمة | D17: =المدخلات!$P$12 -> 403100010
A19: ='[3]حساب الكميات'!AO270 -> سعر الفيلا مع السور(بدون الضريبة) | E19: ='حساب الكميات'!$AO$241 -> 67665
A21: يقوم الطرف الثاني بتنفيذ وانشاء وانجاز وصيانة المشروع المذكور اعلاه لقاء مبلغ وقدره
A22: =المدخلات!$AD$13 -> 0 | I22: درهم اماراتي
A23: و ذلك حسب المتفق عليه والمعتمد وفق للمناقصة التي جرت
A25: توقيع وختم المقاول | D25: توقيع وختم المالك | G25: توقيع وختم الاستشاري
A32: بنود العقد
A34: كافة مستندات المشروع و جميع متعلقاته متكاملة فيما بينها و تشمل المشروع ككل أي بحال عدم ذكر اي بند بالمواصفات او المخططات وتم ذكره بجدول الكميات او المخططات المعتمدة أو اي مستند اخر غير ذلك , والعكس صحيح على المقاول الالتزام به و العمل على تضمينه بأعمال المشروع اينما ذكر .علي المقاول ارجاع العقد موقع علي كل صفحة والمواصافات و المخططات وتوقيعه عليها يعتبر انه اطلع علي جميع تفاصيل المشروع
A36: 1 | B36: الاطلاع علي جميع مخططات المشروع | I36: =A36 -> 1
A37: على المقاول قبل توقيع العقد الاطلاع على المخططات و المواصفات و الشروط و التأكد من تطابق جميع المخططات الانشائية والمعمارية والخدمات و المناظير 3D وتنبيه الاستشاري لأي اختلاف في تطابق المخططات وذلك لتفادي التغيير و التعديل في الموقع قبل التنفيذ و في حالة عدم تنبيه الاستشاري بوجود اختلاف قبل الشروع في العمل يتحمل المقاول كامل المسؤولية في التعديلات المطلوبة و التاخير المترتب عن ذلك و اعتبار أن توقيعه عليها يعني موافقته على جميع ما ورد بها وتعتبر المناظير المقدمة من الاستشاري في ملف المناقصة هي المعتمدة من ناحية الشكل و التشطيبات في حال اختلاف مع المخططات المعتمدة .
B38: إصدار التعليمات, الرسوم | D38: إصدار التعليمات, الرسوم
A39: لا يحق للمالك اصدار اي تعليمات للمقاول تتعلق بتنفيذ المشروع الا عن طريق الاستشاري
A40: 2 | B40: مقاولي الباطن | G40: 2 | I40: =A40 -> 2
A41: يجوز للطرف الثاني اسناد جزء من الاعمال الى مقاولي الباطن المعتمدين والمسجلين لدى البلدية بموجب موافقة خطية من الاستشاري
A42: يكون المقاول مسؤول مسؤولية كاملة عن اعمال المقاول الباطن من حيث الجودة والتنفيذ واصول الصناعه والضمانات
A43: يتعهد الطرف الثاني بالتنسيق بين جميع المقاولين الباطن دون اي استثناء ودون اي احقية في المطالبة باي مبلغ اضافة نظير ذلك.
A45: 3 | B45: فسخ التعاقد | G45: 3 | I45: =A45 -> 3
A46: يحق للمهندس الاستشاري فسخ العقد في الحالات
A47: اذا تاخر المقاول عن بدء الاعمال بعد تسليم الموقع
A48: اذا تاخر المقاول في اتمام العمل وتسليمه في المواعيد المحدده لكل مرحلة في الجدول الزمني المعتمد
A49: اذا اظهر المقاول بطئا في سير العمل لدرجة يرى الاستشاري منها عدم قدرة الطرف الثاني على اتمام العمل في موعده على ان يقوم الاستشاري بتنبيه المقاول خطيا .
A50: اذا اخل المقاول ببرنامج العمل المحدد بشكل يؤثر على مستوى التنفيذ او الاخلال بالمواصفات المتفق عليها
A51: اذا انسحب المقاول عن العمل او تركه او افلس
A52: اذا اسند الطرف الثاني العمل لمقاول باطن دون اخطار الاستشاري
A53: في حال تاخير الطرف الاول عن سداد اي من مستحقات الطرف الثاني في موعد اقصاه 30 يوم فمن حق الطرف الثاني التوقف عن العمل وذلك بعد اخطار الاستشاري خطيا وتحسب فتره التاخير على المالك لصالح المقاول كمدة اضافية للمشروع.
A54: يحق للطرف الثاني الغاء التعاقد في حالة تاخير المالك باختيار التشطيبات مما يعود بالضرر علي المقاول
A55: 4 | B55: الاثار المترتبة على فسخ العقد | G55: 4 | I55: =A55 -> 4
A56: حساب غرامة التاخير على الطرف الثاني طبقا للعقد حتى تاريخ ابلاغ المقاول بقرار السحب.
...

Sheet جدوا زمني
A1: سافانا للإستــــشارات الهــــندسية
A3: مشروع انشاء وانجاز | N3: =المدخلات!P4 -> فيلا دور أرضي و اول وسور
A5: المالك: | N5: =المدخلات!P3 -> احمد ابراهيم النعيمي
A6: المقاول: | N6: =المدخلات!AR10 -> 0
A7: على القسيمة رقم | G7: =المدخلات!AR4 -> 0 | P7: في منطقة | T7: =المدخلات!AR3 -> 0 | Z7: بإمارة | AD7: =[4]INPUT!C7 -> راس الخيمة
A8: قيمة العقد كامل مع ضريبة | Z8: ='حساب الكميات'!$AO$243 -> 71048.25
A10: دفعة خاصة بالمالك | Z10: =Z8-800000 -> -728951.75
B12: التاريخ | G12: =المدخلات!$AR$7 -> 46021 | N12: جدول الدفعات | AA12: دفعة رقم | AH12: 1
A13: الرقم | C13: بيان الاعمال | V13: النسبة الدفعة | X13: نسبة الانجاز | AB13: المدة الزمنية | AG13: الدفعة مع الضريبة
A14: 1 | C14: دفعة مقدمة | N14: مقدم | S14: =AG14/Z8 -> -3.8987824 | V14: 0.38 | AG14: =Z10*V14 -> -277001.66
A15: 2 | C15: تجهيز الموقع | V15: 0 | AB15: 15 | AG15: =Z8*V15 -> 0 | BK15: 800000
A16: 3 | C16: الحفر | V16: 0 | AB16: 5 | AG16: 0
A17: 4 | C17: صب القواعد | V17: 0 | AB17: 20 | AG17: 0
A18: 5 | C18: صب الجسور الارضية | L18: بعد صب الجسور يتم تقديم دفعة بنك | V18: 0 | AB18: 20 | AG18: 0 | AY18: دفغات الاسكان
A19: 6 | C19: صب سقف الدور الارضي | V19: 0.06 | AB19: 48 | AG19: =Z10*V19 -> -43737.105
A20: 7 | C20: صب سقف الدور الاول | L20: بعد صب سقف الاول يتم تقديم دفعة بنك | V20: 0.06 | AB20: 48 | AG20: =Z10*V20 -> -43737.105 | AY20: صبية نظافة | BG20: 0.18 | BM20: =BG20*BK15 -> 144000
A21: 8 | C21: تنفيد اعمال الطابوق الارضي | V21: 0.02 | AB21: 30 | AG21: =Z10*V21 -> -14579.035 | AY21: سقف اارضي | BG21: 0.1 | BM21: =BG21*BK15 -> 80000
A22: 9 | C22: تنفيد اعمال الطابوق الاول | L22: بعد انتهاء مناعمال الطابوق يتم تقديم دفعة بنك | V22: 0.02 | AB22: 30 | AG22: =Z10*V22 -> -14579.035 | AY22: سقف اول | BG22: 0.12 | BM22: =BG22*BK15 -> 96000
A23: 10 | C23: تجهيز التمديدات الكهربايىة والصحية في الجدران | V23: 0.02 | AB23: 30 | AG23: =Z10*V23 -> -14579.035 | AY23: طابوق | BG23: 0.02 | BM23: =BG23*BK15 -> 16000
A24: 12 | C24: اعمال البلاستر الخارجي | V24: 0.02 | AB24: 45 | AG24: =Z10*V24 -> -14579.035 | AY24: بلاستر | BG24: 0.03 | BM24: =BG24*BK15 -> 24000
A25: 13 | C25: اعمال سيراميك جدران الحمامات | V25: 0.02 | AB25: 25 | AG25: =Z10*V25 -> -14579.035 | AY25: بلاستر | BG25: 0 | BM25: =BG25*BK15 -> 0
A26: 14 | C26: اعمال البلاسترالعازل الداخلي | V26: 0.02 | AB26: 30 | AG26: =Z10*V26 -> -14579.035 | AY26: مجموع | BG26: =SUM(BG20:BL25) -> 0.45 | BM26: =SUM(BM20:BT25) -> 360000
A27: 0 | V27: =V26+V25+V24+V23+V22+V21+V20+V19+V18+V17+V16+V15+V14 -> 0.62 | AB27: =SUM(AB17:AF26) -> 326 | AG27: =SUM(AG14:AI26) -> -451950.08 | AY27: برنامج | BM27: =BM26-80000 -> 280000
A28: 15 | C28: تجهيز التمديدات الكهربايىة والصحية في الارضيات | V28: 0.05 | AB28: 20 | AG28: =V28*Z10 -> -36447.588
A29: 16 | C29: أعمال العزل للحمامات و السطح | V29: 0.05 | AB29: 15 | AG29: =V29*Z10 -> -36447.588 | AY29: خاص | BM29: =AG27 -> -451950.08
A30: 17 | C30: تركيب سيراميك الارضي | V30: 0.04 | AB30: 35 | AG30: =V30*Z10 -> -29158.07
A31: 18 | C31: تركيب سيراميك الاول | V31: 0.03 | AB31: 35 | AG31: =V31*Z10 -> -21868.552 | AY31: مجموع | BM31: =BM27+BM29 -> -171950.08
A32: 19 | C32: الانتهاء من تركيب الحجر في الواجهات | V32: 0.08 | AB32: 50 | AG32: =V32*Z10 -> -58316.14
A33: 20 | C33: الانتهاء الالومنيوم والزجاج | V33: 0.04 | AB33: 25 | AG33: =V33*Z10 -> -29158.07 | AY33: المبلغ المفترض يكون مدفوع | BM33: =CA37-CA39 -> 41
A34: 21 | C34: الانتهاء من الاعمال الكهربائية للتسليم | V34: 0.04 | AB34: 20 | AG34: =V34*Z10 -> -29158.07
A35: 22 | C35: الانتهاء من الصبغ الخارجي | V35: 0.04 | AB35: 20 | AG35: =V35*Z10 -> -29158.07 | AY35: الفرق | BM35: =BM31-BM33 -> -171991.08
A36: 23 | C36: تركيب الاطقم الصحية | V36: 0.01 | AB36: 5 | AG36: =V36*Z10 -> -7289.5175
A37: 24 | C37: اعمال الملحق تبدا مع اعمال سيراميك الفيلا | V37: 0 | AB37: 0 | AG37: =V37*Z10 -> 0 | CA37: ='حساب الكميات'!$AO$107 -> 49
A38: 25
A39: قيمة الدفعات | V39: =SUM(V27:W38) -> 1 | AB39: =SUM(AB27:AF38) -> 551 | CA39: ='حساب الكميات'!$AO$106 -> 8
A40: قيمة الضريبة | AB40: =AB39/30 -> 18.366667 | AG40: =SUM(AG27:AI39) -> -728951.75
A41: المجموع الكامل
A42: المالك | M42: الاستشاري | Z42: المقاول
R308: .

Sheet جدول دفعات
A1: سافانا للإستــــشارات الهــــندسية
A3: مشروع انشاء وانجاز | N3: =المدخلات!P4 -> فيلا دور أرضي و اول وسور
A5: المالك: | N5: =المدخلات!P3 -> احمد ابراهيم النعيمي
A6: المقاول: | N6: =المدخلات!AR10 -> 0
A7: على القسيمة رقم | G7: =المدخلات!AR4 -> 0 | P7: في منطقة | T7: =المدخلات!AR3 -> 0 | Z7: بإمارة | AD7: =[4]INPUT!C7 -> راس الخيمة
A8: قيمة العقد كامل بدون ضريبة | Z8: ='حساب الكميات'!AY232 -> 67665
A10: قيمة الضريبة | Z10: =Z8*0.05 -> 3383.25
B12: التاريخ | G12: =المدخلات!P14 -> 0 | N12: جدول الدفعات
A13: الرقم | C13: بيان الاعمال | V13: النسبة | X13: دفعة العقد | AG13: الضريبة
A14: 1 | C14: دفعه مقدمة | V14: 0.15 | X14: =Z8*V14 -> 10149.75 | AG14: =0.05*(AB14+X14) -> 507.4875
A15: 2 | C15: دفعة بعد صب الجسور الأرضية و صبة النظافة الدور الأرضي | V15: 0.08 | X15: =$Z$8*V15 -> 5413.2 | AG15: =0.05*(AB15+X15) -> 270.66
A16: 3 | C16: دفعة بعد صب اعمدة الدور الأرضي | V16: 0.07 | X16: =$Z$8*V16 -> 4736.55 | AG16: =0.05*(AB16+X16) -> 236.8275
A17: 4 | C17: دفعة بعد صب سقف الدور الارضي | V17: 0.08 | X17: =$Z$8*V17 -> 5413.2 | AG17: =0.05*(AB17+X17) -> 270.66
A18: 5 | C18: دفعة بعد صب أعمدة وسقف الدور الأول | V18: 0.1 | X18: =$Z$8*V18 -> 6766.5 | AG18: =0.05*(AB18+X18) -> 338.325
A19: 6 | C19: دفعة بعد الانتهاء من تنفيد اعمال الطابوق | V19: 0.07 | X19: =$Z$8*V19 -> 4736.55 | AG19: =0.05*(AB19+X19) -> 236.8275
A20: 7 | C20: دفعة بعد الانتهاء من اعمال البلاستر الداخلي للارضي | V20: 0.04 | X20: =$Z$8*V20 -> 2706.6 | AG20: =0.05*(AB20+X20) -> 135.33 | AM20: =V22=V21=V20=V19=V18=V17=V16=V15=V14 -> FALSE
A21: 8 | C21: دفعة بعد الانتهاء من اعمال البلاستر الداخلي للاول | V21: 0.04 | X21: =$Z$8*V21 -> 2706.6 | AG21: =0.05*(AB21+X21) -> 135.33
A22: 9 | C22: دفعة بعد الانتهاء من البلاستر الخارجي | V22: 0.06 | X22: =$Z$8*V22 -> 4059.9 | AG22: =0.05*(AB22+X22) -> 202.995
A23: 10 | C23: دفعة بعد الانتهاء من أعمال العزل | V23: 0.08 | X23: =$Z$8*V23 -> 5413.2 | AG23: =0.05*(AB23+X23) -> 270.66
A24: 11 | C24: دفعة بعد الانتهاء من تركيب سيراميك الارضي | V24: 0.02 | X24: =$Z$8*V24 -> 1353.3 | AG24: =0.05*(AB24+X24) -> 67.665
A25: 12 | C25: دفعة بعد الانتهاء من تركيب سيراميك الاول | V25: 0.02 | X25: =$Z$8*V25 -> 1353.3 | AG25: =0.05*(AB25+X25) -> 67.665
A26: 13 | C26: دفعة بعد الانتهاء الالومنيوم والزجاج | V26: 0 | X26: =$Z$8*V26 -> 0 | AG26: =0.05*(AB26+X26) -> 0
A27: 14 | C27: دفعة بعد تركيب الاعمال الصحية | V27: 0.02 | X27: =$Z$8*V27 -> 1353.3 | AG27: =0.05*(AB27+X27) -> 67.665
A28: 15 | C28: دفعة بعد الانتهاء من الاعمال الكهربائية | V28: 0.08 | X28: =$Z$8*V28 -> 5413.2 | AG28: =0.05*(AB28+X28) -> 270.66
A29: 16 | C29: دفعة بعد الانتهاء من الصبغ الخارجي | V29: 0 | X29: =$Z$8*V29 -> 0 | AG29: =0.05*(AB29+X29) -> 0
A30: 17 | C30: دفعة بعد الانتهاء من الاعمال تحت ارضية للسور | V30: 0.04 | X30: =$Z$8*V30 -> 2706.6 | AG30: =0.05*(AB30+X30) -> 135.33
A31: 18 | C31: دفعة بعد الانتهاء من الاعمال فوق ارضية للسور | V31: 0.04 | X31: =$Z$8*V31 -> 2706.6 | AG31: =0.05*(AB31+X31) -> 135.33
A32: 19 | C32: دفعة بعد الانتهاء من تنظيف الموقع | V32: 0.01 | X32: =$Z$8*V32 -> 676.65 | AG32: =0.05*(AB32+X32) -> 33.8325
A33: قيمة الدفعات | V33: =SUM(V14:W32) -> 1 | X33: =SUM(X14:AA32) -> 67665 | AG33: =0.05*(AB33+X33) -> 3383.25
A34: قيمة الضريبة | V34: 0.05 | X34: =X33*V34 -> 3383.25 | AB34: =AB33*V34 -> 0
A35: المجموع الكامل | P35: =X33+X34+AB33+AB34 -> 71048.25
A36: المالك | M36: الاستشاري | Z36: المقاول
R302: .

Sheet  اكميات بنك بدون سور 
B2: حساب كميات المشروع
B3: معلومات المشروع
B4: المالك | O4: =المدخلات!$P$3 -> احمد ابراهيم النعيمي | AC4: المنطقة | AQ4: =المدخلات!$P$11 -> الخران
B5: وصف المشروع | O5: =المدخلات!$P$4 -> فيلا دور أرضي و اول وسور | AC5: رقم القسيمة | AQ5: =المدخلات!$P$12 -> 403100010
B6: مساحة البناء بالمتر المربع | O6: =المدخلات!$AR$5 -> 118 | AC6: مساحة البناء بالقدم المربع | AQ6: =المدخلات!$AY$5 -> 5549
B25: بيانات المقاول
B26: اسم الشركة: | O26: =المدخلات!$AR$3 -> 0 | AC26: المهندس المسؤول: | AQ26: =المدخلات!$AR$6 -> 0
B27: تاريخ المناقصة: | O27: =المدخلات!$AR$7 -> 46021 | AC27: رقم الهاتف: | AQ27: =المدخلات!$AR$11 -> 0
B28: رقم رخصة المقاول: | O28: =المدخلات!$AR$4 -> 0 | AC28: مدة تنفيذ المشروع: | AQ28: =المدخلات!$AR$9 -> 14 شهر
B30: عرض السعر | AQ30: ختم الشركة العارضة
B31: تكلفة انشاء وانجاز الفيلا | AC31: =AO202+AO210 -> 704000
B32: تكلفة انشاء وإنجاز السور | AC32: =AO213 -> 0
B33: تكلفة انشاء وإنجاز الفيلا مع السور | AC33: =AO220 -> 704000
B38: أولا : أعمال الهيكل
B39: (A) أعمال المياه الجوفية والتربة
B40: الرقم | E40: البند | AO40: الوحدة | AS40: الكمية | AW40: السعر | BA40: الإجمالي
B41: A1 | C41: B1 | D41: B1 | E41: أعمال تجفيف المياه الجوفية إن وجدت حسب فحص التربة | F41: عزل الأسقف نوعية ألتك يسعر الفرق فقط | G41: عزل الأسقف نوعية ألتك يسعر الفرق فقط | H41: عزل الأسقف نوعية ألتك يسعر الفرق فقط | I41: عزل الأسقف نوعية ألتك يسعر الفرق فقط | J41: عزل الأسقف نوعية ألتك يسعر الفرق فقط | K41: عزل الأسقف نوعية ألتك يسعر الفرق فقط | L41: عزل الأسقف نوعية ألتك يسعر الفرق فقط | M41: عزل الأسقف نوعية ألتك يسعر الفرق فقط | N41: عزل الأسقف نوعية ألتك يسعر الفرق فقط | O41: عزل الأسقف نوعية ألتك يسعر الفرق فقط | P41: عزل الأسقف نوعية ألتك يسعر الفرق فقط | Q41: عزل الأسقف نوعية ألتك يسعر الفرق فقط | R41: عزل الأسقف نوعية ألتك يسعر الفرق فقط | S41: عزل الأسقف نوعية ألتك يسعر الفرق فقط | T41: عزل الأسقف نوعية ألتك يسعر الفرق فقط | U41: عزل الأسقف نوعية ألتك يسعر الفرق فقط | V41: عزل الأسقف نوعية ألتك يسعر الفرق فقط | W41: عزل الأسقف نوعية ألتك يسعر الفرق فقط | X41: عزل الأسقف نوعية ألتك يسعر الفرق فقط | Y41: عزل الأسقف نوعية ألتك يسعر الفرق فقط | Z41: عزل الأسقف نوعية ألتك يسعر الفرق فقط | AA41: عزل الأسقف نوعية ألتك يسعر الفرق فقط | AB41: عزل الأسقف نوعية ألتك يسعر الفرق فقط | AC41: عزل الأسقف نوعية ألتك يسعر الفرق فقط | AD41: عزل الأسقف نوعية ألتك يسعر الفرق فقط | AE41: عزل الأسقف نوعية ألتك يسعر الفرق فقط | AF41: عزل الأسقف نوعية ألتك يسعر الفرق فقط | AG41: عزل الأسقف نوعية ألتك يسعر الفرق فقط | AH41: عزل الأسقف نوعية ألتك يسعر الفرق فقط | AI41: عزل الأسقف نوعية ألتك يسعر الفرق فقط | AJ41: عزل الأسقف نوعية ألتك يسعر الفرق فقط | AK41: عزل الأسقف نوعية ألتك يسعر الفرق فقط | AL41: عزل الأسقف نوعية ألتك يسعر الفرق فقط | AM41: عزل الأسقف نوعية ألتك يسعر الفرق فقط | AN41: عزل الأسقف نوعية ألتك يسعر الفرق فقط | AO41: L.S | AP41: M2 | AQ41: M2 | AR41: M2 | AS41: 0 | AW41: 0 | BA41: =AW41*AS41 -> 0
B42: A2 | C42: B2 | D42: B2 | E42: أعمال إحلال التربة إن وجدت حسب فحص التربة | F42: الأسمنت بلاستر للحوائط الداخلية. | G42: الأسمنت بلاستر للحوائط الداخلية. | H42: الأسمنت بلاستر للحوائط الداخلية. | I42: الأسمنت بلاستر للحوائط الداخلية. | J42: الأسمنت بلاستر للحوائط الداخلية. | K42: الأسمنت بلاستر للحوائط الداخلية. | L42: الأسمنت بلاستر للحوائط الداخلية. | M42: الأسمنت بلاستر للحوائط الداخلية. | N42: الأسمنت بلاستر للحوائط الداخلية. | O42: الأسمنت بلاستر للحوائط الداخلية. | P42: الأسمنت بلاستر للحوائط الداخلية. | Q42: الأسمنت بلاستر للحوائط الداخلية. | R42: الأسمنت بلاستر للحوائط الداخلية. | S42: الأسمنت بلاستر للحوائط الداخلية. | T42: الأسمنت بلاستر للحوائط الداخلية. | U42: الأسمنت بلاستر للحوائط الداخلية. | V42: الأسمنت بلاستر للحوائط الداخلية. | W42: الأسمنت بلاستر للحوائط الداخلية. | X42: الأسمنت بلاستر للحوائط الداخلية. | Y42: الأسمنت بلاستر للحوائط الداخلية. | Z42: الأسمنت بلاستر للحوائط الداخلية. | AA42: الأسمنت بلاستر للحوائط الداخلية. | AB42: الأسمنت بلاستر للحوائط الداخلية. | AC42: الأسمنت بلاستر للحوائط الداخلية. | AD42: الأسمنت بلاستر للحوائط الداخلية. | AE42: الأسمنت بلاستر للحوائط الداخلية. | AF42: الأسمنت بلاستر للحوائط الداخلية. | AG42: الأسمنت بلاستر للحوائط الداخلية. | AH42: الأسمنت بلاستر للحوائط الداخلية. | AI42: الأسمنت بلاستر للحوائط الداخلية. | AJ42: الأسمنت بلاستر للحوائط الداخلية. | AK42: الأسمنت بلاستر للحوائط الداخلية. | AL42: الأسمنت بلاستر للحوائط الداخلية. | AM42: الأسمنت بلاستر للحوائط الداخلية. | AN42: الأسمنت بلاستر للحوائط الداخلية. | AO42: L.S | AP42: M2 | AQ42: M2 | AR42: M2 | AS42: 0 | AW42: 0 | BA42: =AW42*AS42 -> 0
B43: (A) إجمالي سعر أعمال المياه الجوفية والتربة | AO43: =SUM(BA41:BD42) -> 0
B45: (B) أعمال تحضير وتجهيز الموقع
B46: الرقم | E46: البند | AO46: الوحدة | AS46: الكمية | AW46: السعر | BA46: الإجمالي
B47: B1 | C47: B1 | D47: B1 | E47: تجهيز الموقع السور المؤقت | F47: عزل الأسقف نوعية ألتك يسعر الفرق فقط | G47: عزل الأسقف نوعية ألتك يسعر الفرق فقط | H47: عزل الأسقف نوعية ألتك يسعر الفرق فقط | I47: عزل الأسقف نوعية ألتك يسعر الفرق فقط | J47: عزل الأسقف نوعية ألتك يسعر الفرق فقط | K47: عزل الأسقف نوعية ألتك يسعر الفرق فقط | L47: عزل الأسقف نوعية ألتك يسعر الفرق فقط | M47: عزل الأسقف نوعية ألتك يسعر الفرق فقط | N47: عزل الأسقف نوعية ألتك يسعر الفرق فقط | O47: عزل الأسقف نوعية ألتك يسعر الفرق فقط | P47: عزل الأسقف نوعية ألتك يسعر الفرق فقط | Q47: عزل الأسقف نوعية ألتك يسعر الفرق فقط | R47: عزل الأسقف نوعية ألتك يسعر الفرق فقط | S47: عزل الأسقف نوعية ألتك يسعر الفرق فقط | T47: عزل الأسقف نوعية ألتك يسعر الفرق فقط | U47: عزل الأسقف نوعية ألتك يسعر الفرق فقط | V47: عزل الأسقف نوعية ألتك يسعر الفرق فقط | W47: عزل الأسقف نوعية ألتك يسعر الفرق فقط | X47: عزل الأسقف نوعية ألتك يسعر الفرق فقط | Y47: عزل الأسقف نوعية ألتك يسعر الفرق فقط | Z47: عزل الأسقف نوعية ألتك يسعر الفرق فقط | AA47: عزل الأسقف نوعية ألتك يسعر الفرق فقط | AB47: عزل الأسقف نوعية ألتك يسعر الفرق فقط | AC47: عزل الأسقف نوعية ألتك يسعر الفرق فقط | AD47: عزل الأسقف نوعية ألتك يسعر الفرق فقط | AE47: عزل الأسقف نوعية ألتك يسعر الفرق فقط | AF47: عزل الأسقف نوعية ألتك يسعر الفرق فقط | AG47: عزل الأسقف نوعية ألتك يسعر الفرق فقط | AH47: عزل الأسقف نوعية ألتك يسعر الفرق فقط | AI47: عزل الأسقف نوعية ألتك يسعر الفرق فقط | AJ47: عزل الأسقف نوعية ألتك يسعر الفرق فقط | AK47: عزل الأسقف نوعية ألتك يسعر الفرق فقط | AL47: عزل الأسقف نوعية ألتك يسعر الفرق فقط | AM47: عزل الأسقف نوعية ألتك يسعر الفرق فقط | AN47: عزل الأسقف نوعية ألتك يسعر الفرق فقط | AO47: مقطوغ | AP47: M2 | AQ47: M2 | AR47: M2 | AS47: - | AW47: - | BA47: -
